<?xml version="1.0"?>
<robot xmlns:xacro="http://www.ros.org/wiki/xacro" >
    <!-- Adding macros for computation of inertial matrix so as to create 
    a close to realistic model -->
    <!-- property macros describing dimensions of the wheels -->
    <!-- assuming wheels to be of a hypothetical material with density 15 -->
    <xacro:property name="wheel_density" value="15"/>
    <xacro:property name="wheel_radius" value="0.15"/>
    <xacro:property name="wheel_length" value="0.1"/>
    <xacro:property name="pi" value="3.141592654"/>    
    <xacro:property name="body_mass" value="10"/>

    <xacro:property name="wheel_mass" value="${wheel_density*pi*wheel_radius*wheel_radius*wheel_length}"/>
        
    <xacro:property name="Iz_wheel" value="${0.5*wheel_mass*wheel_radius*wheel_radius}" />
    <xacro:property name="I_wheel" value="${(1.0/12.0)*wheel_mass*(3.0*wheel_radius*wheel_radius+wheel_length*wheel_length)}"/>
    
    <!-- creating the inertial macros -->
    <xacro:macro name="inertia_wheel">
        <inertial>
            <origin xyz="0.0 0.0 0.0" rpy="0.0 0.0 0.0"/>
            <mass value="${wheel_mass}"/>
            <inertia ixx="${I_wheel}" ixy="0.0" ixz="0.0" iyy="${I_wheel}" iyz="0.0" izz="${Iz_wheel}"/>
        </inertial>
    </xacro:macro>

<!-- creating a xacro macro for the template of the wheels -->
    <xacro:macro name="wheel" params="name x y file_path">
        <link name="wheel_${name}_link">
            <xacro:inertia_wheel />
            
            <visual name="">
                <origin xyz="0.0 0.0 0.0" rpy="0.0 0.0 0.0"/>
                <geometry>
                    <mesh filename="${file_path}" scale="0.005 0.005 0.005"/>
                </geometry>
                <material name="black">
                    <color rgba="0.0 0.0 0.0 1.0"/>
                </material>
            </visual>
            <collision>
                <origin xyz="0.0 0.0 0.0" rpy="0.0 0.0 0.0"/>
                <geometry>
                    <cylinder radius="0.15" length="0.1"/>
                </geometry>
            </collision>
        </link>

        <joint name="wheel_${name}_joint" type="continuous">
            <origin xyz="${x} ${y} .0" rpy="0 0.0 0.0"/>
            <parent link="base_link"/>
            <child link="wheel_${name}_link"/>
            <axis xyz="0 1 0"/>
            <limit effort="100.0" velocity="100.0"/>
            <dynamics damping="1.0" friction="1.0"/>
            
        </joint>

        <gazebo reference="wheel_${name}_link">
            <mu1>0.2</mu1>
            <mu2>0.2</mu2>
            <material>Gazebo/Black</material>
        </gazebo>

    </xacro:macro>

</robot>


